~/HirewayManager$ python3 scripts/run_data_import.py
2025-01-03 01:39:12 - INFO - Starting O*NET data import process
2025-01-03 01:39:12 - INFO - Running import_onet_to_db.py...
2025-01-03 01:39:14 - ERROR - Error running import_onet_to_db.py:

2025-01-03 01:39:13,260 - INFO - Starting data import process...
2025-01-03 01:39:13,260 - INFO - Reading CSV files...
2025-01-03 01:39:13,310 - INFO - Successfully read 1016 occupations and 55120 alternative titles
2025-01-03 01:39:14,168 - INFO - Successfully connected to database
2025-01-03 01:39:14,168 - INFO - Processing major groups...
2025-01-03 01:39:14,168 - ERROR - Error during import: 'code'
2025-01-03 01:39:14,168 - ERROR - Failed to process data files: 'code'
Traceback (most recent call last):
  File "/home/runner/HirewayManager/.pythonlibs/lib/python3.11/site-packages/pandas/core/indexes/base.py", line 3805, in get_loc
    return self._engine.get_loc(casted_key)
           ^^^^^^^^^^^^^^^^^^^^^^^^^^^^^^^^
  File "index.pyx", line 167, in pandas._libs.index.IndexEngine.get_loc
  File "index.pyx", line 196, in pandas._libs.index.IndexEngine.get_loc
  File "pandas/_libs/hashtable_class_helper.pxi", line 7081, in pandas._libs.hashtable.PyObjectHashTable.get_item
  File "pandas/_libs/hashtable_class_helper.pxi", line 7089, in pandas._libs.hashtable.PyObjectHashTable.get_item
KeyError: 'code'

The above exception was the direct cause of the following exception:

Traceback (most recent call last):
  File "/home/runner/HirewayManager/scripts/import_onet_to_db.py", line 221, in <module>
    import_data()
  File "/home/runner/HirewayManager/scripts/import_onet_to_db.py", line 91, in import_data
    for code in sorted(set([str(code)[:2] for code in occ_data['code'] if pd.notna(code)])):
                                                      ~~~~~~~~^^^^^^^^
  File "/home/runner/HirewayManager/.pythonlibs/lib/python3.11/site-packages/pandas/core/frame.py", line 4102, in __getitem__
    indexer = self.columns.get_loc(key)
              ^^^^^^^^^^^^^^^^^^^^^^^^^
  File "/home/runner/HirewayManager/.pythonlibs/lib/python3.11/site-packages/pandas/core/indexes/base.py", line 3812, in get_loc
    raise KeyError(key) from err
KeyError: 'code'

Traceback (most recent call last):
  File "/home/runner/HirewayManager/scripts/run_data_import.py", line 41, in <module>
    main()
  File "/home/runner/HirewayManager/scripts/run_data_import.py", line 36, in main
    run_script("import_onet_to_db.py")
  File "/home/runner/HirewayManager/scripts/run_data_import.py", line 15, in run_script
    result = subprocess.run(
             ^^^^^^^^^^^^^^^
  File "/nix/store/clx0mcir7qw8zk36zbr4jra789g3knf6-python3-3.11.10/lib/python3.11/subprocess.py", line 571, in run
    raise CalledProcessError(retcode, process.args,
subprocess.CalledProcessError: Command '['/home/runner/HirewayManager/.pythonlibs/bin/python3', 'scripts/import_onet_to_db.py']' returned non-zero exit status 1.
~/HirewayManager$ 